Workbook

Sheet Start Here
B1: SavingsClub 2026 Monthly Budget Planner
B2: Helping you keep more of what you earn · savingsclub.com
B4: How to use this planner
B5: 1. Open the Monthly Budget tab. Type your own numbers into the light green cells.
B6: 2. The sample numbers are just examples. Type right over them.
B7: 3. Fill in Budgeted (your plan) and Actual (what really happened) for each line.
B8: 4. The Dashboard tab updates on its own. No math needed from you.
B10: What the colors mean
B11: GREEN means good. You came in under budget, or you are hitting your savings target.
B12: RED means watch out. You spent more than you planned, or a category is over target.
B13: The Difference column and the Dashboard change color automatically as you type.
B15: The 50 / 30 / 20 rule (built into your Dashboard)
... B22: Made by the SavingsClub Research Team · Free forever · savingsclub.com

Sheet Monthly Budget
A1: SavingsClub | 2026 Monthly Budget Planner
A2: Helping you keep more of what you earn · savingsclub.com | D2: Month: ______________
A4: INCOME
A5: Source | C5: Expected | D5: Received | E5: Difference
A6: Primary take-home pay | C6: 4200 | D6: 4200 | E6: =D6-C6 -> 0
A7: Side income / second job | C7: 600 | D7: 720 | E7: =D7-C7 -> 120
A8: Other income | C8: 0 | D8: 0 | E8: =D8-C8 -> 0
A9: Total income | C9: =SUM(C6:C8) -> 4800 | D9: =SUM(D6:D8) -> 4920
A11: FIXED EXPENSES
A12: Category | B12: Type | C12: Budgeted | D12: Actual | E12: Difference
A13: Rent / Mortgage | B13: Need | C13: 1400 | D13: 1400 | E13: =D13-C13 -> 0
A14: Utilities (power, water, gas) | B14: Need | C14: 180 | D14: 205 | E14: =D14-C14 -> 25
A15: Insurance (health, auto, home) | B15: Need | C15: 240 | D15: 240 | E15: =D15-C15 -> 0
A16: Phone / Internet | B16: Need | C16: 120 | D16: 120 | E16: =D16-C16 -> 0
A17: Car payment | B17: Need | C17: 320 | D17: 320 | E17: =D17-C17 -> 0
A18: Subscriptions / memberships | B18: Want | C18: 55 | D18: 72 | E18: =D18-C18 -> 17
A19: Childcare | B19: Need | C19: 0 | D19: 0 | E19: =D19-C19 -> 0
A20: Other fixed | B20: Need | C20: 0 | D20: 0 | E20: =D20-C20 -> 0
A21: Total fixed expenses | C21: =SUM(C13:C20) -> 2315 | D21: =SUM(D13:D20) -> 2357
A23: VARIABLE EXPENSES
A24: Category | B24: Type | C24: Budgeted | D24: Actual | E24: Difference
A25: Groceries | B25: Need | C25: 520 | D25: 540 | E25: =D25-C25 -> 20
A26: Gas / Transit | B26: Need | C26: 160 | D26: 175 | E26: =D26-C26 -> 15
A27: Dining out | B27: Want | C27: 180 | D27: 240 | E27: =D27-C27 -> 60
A28: Entertainment | B28: Want | C28: 90 | D28: 110 | E28: =D28-C28 -> 20
A29: Shopping / clothing | B29: Want | C29: 120 | D29: 95 | E29: =D29-C29 -> -25
A30: Health / Medical | B30: Need | C30: 60 | D30: 45 | E30: =D30-C30 -> -15
A31: Personal care | B31: Want | C31: 50 | D31: 50 | E31: =D31-C31 -> 0
A32: Other variable | B32: Want | C32: 0 | D32: 0 | E32: =D32-C32 -> 0
A33: Total variable expenses | C33: =SUM(C25:C32) -> 1180 | D33: =SUM(D25:D32) -> 1255
A35: SAVINGS & GOALS
A36: Category | B36: Type | C36: Budgeted | D36: Actual | E36: Difference
A37: Emergency fund | B37: Save | C37: 300 | D37: 300 | E37: =D37-C37 -> 0
A38: Retirement / 401(k) | B38: Save | C38: 250 | D38: 250 | E38: =D38-C38 -> 0
A39: Investments | B39: Save | C39: 100 | D39: 100 | E39: =D39-C39 -> 0
A40: Specific savings goal | B40: Save | C40: 150 | D40: 150 | E40: =D40-C40 -> 0
A41: Total savings | C41: =SUM(C37:C40) -> 800 | D41: =SUM(D37:D40) -> 800
A43: DEBT PAYOFF (beyond minimums)
A44: Category | B44: Type | C44: Budgeted | D44: Actual | E44: Difference
A45: Credit cards | B45: Save | C45: 200 | D45: 200 | E45: =D45-C45 -> 0
...

Sheet Dashboard
B1: Your Money at a Glance
B2: Auto-updates as you fill in the Monthly Budget tab
B4: Total income | C4: Total money out | D4: Left over
B5: ='Monthly Budget'!D9 -> 4920 | C5: =('Monthly Budget'!D21+'Monthly Budget'!D33+'Monthly Budget'!D41+'Monthly Budget'!D48) -> 4792 | D5: ='Monthly Budget'!D9-('Monthly Budget'!D21+'Monthly Budget'!D33+'Monthly Budget'!D41+'Monthly Budget'!D48) -> 128
B7: Savings + debt payoff rate | D7: =IFERROR(('Monthly Budget'!D41+'Monthly Budget'!D48)/'Monthly Budget'!D9,0) -> 0.2398374
B9: The 50 / 30 / 20 Check
B10: Bucket | C10: Your amount | D10: Your % | E10: Target
B11: Needs (must-haves) | C11: =SUMIF('Monthly Budget'!B13:B47,"Need",'Monthly Budget'!D13:D47) -> 3045 | D11: =IFERROR(C11/'Monthly Budget'!D9,0) -> 0.61890244 | E11: 0.5
B12: Wants (nice-to-haves) | C12: =SUMIF('Monthly Budget'!B13:B47,"Want",'Monthly Budget'!D13:D47) -> 567 | D12: =IFERROR(C12/'Monthly Budget'!D9,0) -> 0.1152439 | E12: 0.3
B13: Savings + debt | C13: =SUMIF('Monthly Budget'!B13:B47,"Save",'Monthly Budget'!D13:D47) -> 1180 | D13: =IFERROR(C13/'Monthly Budget'!D9,0) -> 0.2398374 | E13: 0.2
B15: Want to go deeper? Use our free calculators to plan your debt payoff, retirement, and take-home pay at savingsclub.com. Keep more of what you earn.
